#output: test
#output: 3

import testsupport.TestException;

val a: int;
try {
	throw new TestException("test");
} catch ex {
	println("test");
} finally {
	a = 3;
}

println(a);
